Workbook

Sheet Методика
A1: Фаза 1 — Экспертное оценивание и нечёткий коллективный TOPSIS
A6: Код | B6: Критерий | C6: Тип | D6: Шкала | E6: Лучшее значение | F6: Комментарий
A7: K1 | B7: Практическая значимость | C7: Benefit | D7: 0–10 | E7: Больше | F7: Одинаковый критерий применяется ко всем 4 концепциям
A8: K2 | B8: Функциональная содержательность | C8: Benefit | D8: 0–10 | E8: Больше | F8: Одинаковый критерий применяется ко всем 4 концепциям
A9: K3 | B9: Потенциал интеграции и развития | C9: Benefit | D9: 0–10 | E9: Больше | F9: Одинаковый критерий применяется ко всем 4 концепциям
A10: K4 | B10: Демонстрационная и исследовательская ценность | C10: Benefit | D10: 0–10 | E10: Больше | F10: Одинаковый критерий применяется ко всем 4 концепциям
A11: K5 | B11: Трудоёмкость реализации MVP | C11: Cost | D11: 0–10 | E11: Меньше | F11: Одинаковый критерий применяется ко всем 4 концепциям
A12: K6 | B12: Зависимость MVP от внешних ресурсов | C12: Cost | D12: 0–10 | E12: Меньше | F12: Одинаковый критерий применяется ко всем 4 концепциям
A13: K7 | B13: Сложность эксплуатации и сопровождения MVP | C13: Cost | D13: 0–10 | E13: Меньше | F13: Одинаковый критерий применяется ко всем 4 концепциям
A16: Материал | B16: Ссылка | D16: Легенда критериев
A17: Репозиторий проекта | B17: https://github.com/Redin666/project_management | D17: Benefit ↑ | F17: Больше — лучше
A18: Issue #15 — оценивание | B18: https://github.com/Redin666/project_management/issues/15 | D18: Cost ↓ | F18: Меньше — лучше
A19: Issue #5 — TOPSIS | B19: https://github.com/Redin666/project_management/issues/5
A22: Метод расчёта
A23: 1) Каждый эксперт выставляет одну целую оценку 0–10. 2) Три оценки объединяются в нечёткое число (l, m, u) = (MIN, MEDIAN, MAX). 3) Важность критерия преобразуется в нечёткий вес делением каждой компоненты на 10. 4) Benefit: (l/U, m/U, u/U), где U = max верхней границы. 5) Cost: (L/u, L/m, L/l), где L = min нижней границы. 6) После взвешивания определяются идеал/антиидеал, расстояния и CC = D-/(D+ + D-).

Sheet Оценки
A1: Экспертное оценивание — черновой набор для подтверждения
A6: Важность критериев
A7: Код | B7: Критерий | C7: Тип | D7: Никита Редин | E7: Павел Шатков | F7: Владислав Полищук | G7: l = MIN | H7: m = MEDIAN | I7: u = MAX
A8: K1 | B8: Практическая значимость | C8: Benefit ↑ | D8: 10 | E8: 9 | F8: 9 | G8: =MIN(D8:F8) -> 9 | H8: =MEDIAN(D8:F8) -> 9 | I8: =MAX(D8:F8) -> 10
A9: K2 | B9: Функциональная содержательность | C9: Benefit ↑ | D9: 8 | E9: 8 | F9: 9 | G9: =MIN(D9:F9) -> 8 | H9: =MEDIAN(D9:F9) -> 8 | I9: =MAX(D9:F9) -> 9
A10: K3 | B10: Потенциал интеграции и развития | C10: Benefit ↑ | D10: 8 | E10: 7 | F10: 8 | G10: =MIN(D10:F10) -> 7 | H10: =MEDIAN(D10:F10) -> 8 | I10: =MAX(D10:F10) -> 8
A11: K4 | B11: Демонстрационная и исследовательская ценность | C11: Benefit ↑ | D11: 9 | E11: 8 | F11: 9 | G11: =MIN(D11:F11) -> 8 | H11: =MEDIAN(D11:F11) -> 9 | I11: =MAX(D11:F11) -> 9
A12: K5 | B12: Трудоёмкость реализации MVP | C12: Cost ↓ | D12: 9 | E12: 10 | F12: 9 | G12: =MIN(D12:F12) -> 9 | H12: =MEDIAN(D12:F12) -> 9 | I12: =MAX(D12:F12) -> 10
A13: K6 | B13: Зависимость MVP от внешних ресурсов | C13: Cost ↓ | D13: 7 | E13: 8 | F13: 8 | G13: =MIN(D13:F13) -> 7 | H13: =MEDIAN(D13:F13) -> 8 | I13: =MAX(D13:F13) -> 8
A14: K7 | B14: Сложность эксплуатации и сопровождения MVP | C14: Cost ↓ | D14: 7 | E14: 8 | F14: 7 | G14: =MIN(D14:F14) -> 7 | H14: =MEDIAN(D14:F14) -> 7 | I14: =MAX(D14:F14) -> 8
A17: Оценки альтернатив
A18: Альтернатива | B18: Критерий | C18: Тип | D18: Никита Редин | E18: Павел Шатков | F18: Владислав Полищук | G18: l = MIN | H18: m = MEDIAN | I18: u = MAX
A19: A1 — Система управления результатами тестирования на проникновение | B19: K1 — Практическая значимость | C19: Benefit ↑ | D19: 9 | E19: 9 | F19: 10 | G19: =MIN(D19:F19) -> 9 | H19: =MEDIAN(D19:F19) -> 9 | I19: =MAX(D19:F19) -> 10
A20: A1 — Система управления результатами тестирования на проникновение | B20: K2 — Функциональная содержательность | C20: Benefit ↑ | D20: 8 | E20: 8 | F20: 9 | G20: =MIN(D20:F20) -> 8 | H20: =MEDIAN(D20:F20) -> 8 | I20: =MAX(D20:F20) -> 9
A21: A1 — Система управления результатами тестирования на проникновение | B21: K3 — Потенциал интеграции и развития | C21: Benefit ↑ | D21: 8 | E21: 7 | F21: 8 | G21: =MIN(D21:F21) -> 7 | H21: =MEDIAN(D21:F21) -> 8 | I21: =MAX(D21:F21) -> 8
A22: A1 — Система управления результатами тестирования на проникновение | B22: K4 — Демонстрационная и исследовательская ценность | C22: Benefit ↑ | D22: 10 | E22: 9 | F22: 9 | G22: =MIN(D22:F22) -> 9 | H22: =MEDIAN(D22:F22) -> 9 | I22: =MAX(D22:F22) -> 10
A23: A1 — Система управления результатами тестирования на проникновение | B23: K5 — Трудоёмкость реализации MVP | C23: Cost ↓ | D23: 6 | E23: 6 | F23: 5 | G23: =MIN(D23:F23) -> 5 | H23: =MEDIAN(D23:F23) -> 6 | I23: =MAX(D23:F23) -> 6
A24: A1 — Система управления результатами тестирования на проникновение | B24: K6 — Зависимость MVP от внешних ресурсов | C24: Cost ↓ | D24: 4 | E24: 5 | F24: 4 | G24: =MIN(D24:F24) -> 4 | H24: =MEDIAN(D24:F24) -> 4 | I24: =MAX(D24:F24) -> 5
A25: A1 — Система управления результатами тестирования на проникновение | B25: K7 — Сложность эксплуатации и сопровождения MVP | C25: Cost ↓ | D25: 5 | E25: 5 | F25: 5 | G25: =MIN(D25:F25) -> 5 | H25: =MEDIAN(D25:F25) -> 5 | I25: =MAX(D25:F25) -> 5
A26: A2 — Система контроля безопасности процесса разработки ПО | B26: K1 — Практическая значимость | C26: Benefit ↑ | D26: 9 | E26: 10 | F26: 9 | G26: =MIN(D26:F26) -> 9 | H26: =MEDIAN(D26:F26) -> 9 | I26: =MAX(D26:F26) -> 10
A27: A2 — Система контроля безопасности процесса разработки ПО | B27: K2 — Функциональная содержательность | C27: Benefit ↑ | D27: 9 | E27: 9 | F27: 9 | G27: =MIN(D27:F27) -> 9 | H27: =MEDIAN(D27:F27) -> 9 | I27: =MAX(D27:F27) -> 9
A28: A2 — Система контроля безопасности процесса разработки ПО | B28: K3 — Потенциал интеграции и развития | C28: Benefit ↑ | D28: 10 | E28: 9 | F28: 10 | G28: =MIN(D28:F28) -> 9 | H28: =MEDIAN(D28:F28) -> 10 | I28: =MAX(D28:F28) -> 10
A29: A2 — Система контроля безопасности процесса разработки ПО | B29: K4 — Демонстрационная и исследовательская ценность | C29: Benefit ↑ | D29: 8 | E29: 8 | F29: 8 | G29: =MIN(D29:F29) -> 8 | H29: =MEDIAN(D29:F29) -> 8 | I29: =MAX(D29:F29) -> 8
A30: A2 — Система контроля безопасности процесса разработки ПО | B30: K5 — Трудоёмкость реализации MVP | C30: Cost ↓ | D30: 8 | E30: 9 | F30: 8 | G30: =MIN(D30:F30) -> 8 | H30: =MEDIAN(D30:F30) -> 8 | I30: =MAX(D30:F30) -> 9
... A46: A4 — Система управления проверками защищённости информационных систем | B46: K7 — Сложность эксплуатации и сопровождения MVP | C46: Cost ↓ | D46: 4 | E46: 4 | F46: 4 | G46: =MIN(D46:F46) -> 4 | H46: =MEDIAN(D46:F46) -> 4 | I46: =MAX(D46:F46) -> 4

Sheet Коллективные
A1: Коллективные нечёткие оценки (l, m, u)
A3: Нечёткие веса критериев
A4: Критерий | B4: l | C4: m | D4: u | E4: Вес (l;m;u) / 10
A5: K1 — Практическая значимость | B5: =Оценки!G8/10 -> 0.9 | C5: =Оценки!H8/10 -> 0.9 | D5: =Оценки!I8/10 -> 1 | E5: =TEXT(B5,"0.000")&"; "&TEXT(C5,"0.000")&"; "&TEXT(D5,"0.000") -> #VALUE!
A6: K2 — Функциональная содержательность | B6: =Оценки!G9/10 -> 0.8 | C6: =Оценки!H9/10 -> 0.8 | D6: =Оценки!I9/10 -> 0.9 | E6: =TEXT(B6,"0.000")&"; "&TEXT(C6,"0.000")&"; "&TEXT(D6,"0.000") -> #VALUE!
A7: K3 — Потенциал интеграции и развития | B7: =Оценки!G10/10 -> 0.7 | C7: =Оценки!H10/10 -> 0.8 | D7: =Оценки!I10/10 -> 0.8 | E7: =TEXT(B7,"0.000")&"; "&TEXT(C7,"0.000")&"; "&TEXT(D7,"0.000") -> #VALUE!
A8: K4 — Демонстрационная и исследовательская ценность | B8: =Оценки!G11/10 -> 0.8 | C8: =Оценки!H11/10 -> 0.9 | D8: =Оценки!I11/10 -> 0.9 | E8: =TEXT(B8,"0.000")&"; "&TEXT(C8,"0.000")&"; "&TEXT(D8,"0.000") -> #VALUE!
A9: K5 — Трудоёмкость реализации MVP | B9: =Оценки!G12/10 -> 0.9 | C9: =Оценки!H12/10 -> 0.9 | D9: =Оценки!I12/10 -> 1 | E9: =TEXT(B9,"0.000")&"; "&TEXT(C9,"0.000")&"; "&TEXT(D9,"0.000") -> #VALUE!
A10: K6 — Зависимость MVP от внешних ресурсов | B10: =Оценки!G13/10 -> 0.7 | C10: =Оценки!H13/10 -> 0.8 | D10: =Оценки!I13/10 -> 0.8 | E10: =TEXT(B10,"0.000")&"; "&TEXT(C10,"0.000")&"; "&TEXT(D10,"0.000") -> #VALUE!
A11: K7 — Сложность эксплуатации и сопровождения MVP | B11: =Оценки!G14/10 -> 0.7 | C11: =Оценки!H14/10 -> 0.7 | D11: =Оценки!I14/10 -> 0.8 | E11: =TEXT(B11,"0.000")&"; "&TEXT(C11,"0.000")&"; "&TEXT(D11,"0.000") -> #VALUE!
A14: Коллективная матрица решений
A15: Альтернатива | B15: K1 | E15: K2 | H15: K3 | K15: K4 | N15: K5 | Q15: K6 | T15: K7
B16: l | C16: m | D16: u | E16: l | F16: m | G16: u | H16: l | I16: m | J16: u | K16: l | L16: m | M16: u | N16: l | O16: m | P16: u | Q16: l | R16: m | S16: u | T16: l | U16: m | V16: u
A17: A1 — Система управления результатами тестирования на проникновение | B17: =Оценки!G19 -> 9 | C17: =Оценки!H19 -> 9 | D17: =Оценки!I19 -> 10 | E17: =Оценки!G20 -> 8 | F17: =Оценки!H20 -> 8 | G17: =Оценки!I20 -> 9 | H17: =Оценки!G21 -> 7 | I17: =Оценки!H21 -> 8 | J17: =Оценки!I21 -> 8 | K17: =Оценки!G22 -> 9 | L17: =Оценки!H22 -> 9 | M17: =Оценки!I22 -> 10 | N17: =Оценки!G23 -> 5 | O17: =Оценки!H23 -> 6 | P17: =Оценки!I23 -> 6 | Q17: =Оценки!G24 -> 4 | R17: =Оценки!H24 -> 4 | S17: =Оценки!I24 -> 5 | T17: =Оценки!G25 -> 5 | U17: =Оценки!H25 -> 5 | V17: =Оценки!I25 -> 5
A18: A2 — Система контроля безопасности процесса разработки ПО | B18: =Оценки!G26 -> 9 | C18: =Оценки!H26 -> 9 | D18: =Оценки!I26 -> 10 | E18: =Оценки!G27 -> 9 | F18: =Оценки!H27 -> 9 | G18: =Оценки!I27 -> 9 | H18: =Оценки!G28 -> 9 | I18: =Оценки!H28 -> 10 | J18: =Оценки!I28 -> 10 | K18: =Оценки!G29 -> 8 | L18: =Оценки!H29 -> 8 | M18: =Оценки!I29 -> 8 | N18: =Оценки!G30 -> 8 | O18: =Оценки!H30 -> 8 | P18: =Оценки!I30 -> 9 | Q18: =Оценки!G31 -> 7 | R18: =Оценки!H31 -> 8 | S18: =Оценки!I31 -> 8 | T18: =Оценки!G32 -> 8 | U18: =Оценки!H32 -> 8 | V18: =Оценки!I32 -> 9
A19: A3 — Система регистрации и обработки инцидентов информационной безопасности | B19: =Оценки!G33 -> 10 | C19: =Оценки!H33 -> 10 | D19: =Оценки!I33 -> 10 | E19: =Оценки!G34 -> 9 | F19: =Оценки!H34 -> 9 | G19: =Оценки!I34 -> 9 | H19: =Оценки!G35 -> 9 | I19: =Оценки!H35 -> 9 | J19: =Оценки!I35 -> 9 | K19: =Оценки!G36 -> 8 | L19: =Оценки!H36 -> 9 | M19: =Оценки!I36 -> 9 | N19: =Оценки!G37 -> 7 | O19: =Оценки!H37 -> 8 | P19: =Оценки!I37 -> 8 | Q19: =Оценки!G38 -> 6 | R19: =Оценки!H38 -> 7 | S19: =Оценки!I38 -> 7 | T19: =Оценки!G39 -> 7 | U19: =Оценки!H39 -> 8 | V19: =Оценки!I39 -> 8
A20: A4 — Система управления проверками защищённости информационных систем | B20: =Оценки!G40 -> 7 | C20: =Оценки!H40 -> 7 | D20: =Оценки!I40 -> 8 | E20: =Оценки!G41 -> 6 | F20: =Оценки!H41 -> 7 | G20: =Оценки!I41 -> 7 | H20: =Оценки!G42 -> 6 | I20: =Оценки!H42 -> 6 | J20: =Оценки!I42 -> 7 | K20: =Оценки!G43 -> 7 | L20: =Оценки!H43 -> 7 | M20: =Оценки!I43 -> 8 | N20: =Оценки!G44 -> 4 | O20: =Оценки!H44 -> 5 | P20: =Оценки!I44 -> 5 | Q20: =Оценки!G45 -> 3 | R20: =Оценки!H45 -> 3 | S20: =Оценки!I45 -> 4 | T20: =Оценки!G46 -> 4 | U20: =Оценки!H46 -> 4 | V20: =Оценки!I46 -> 4

Sheet TOPSIS
A1: Нечёткий коллективный TOPSIS — выбор концепции проекта
A2: Расчёт по 4 альтернативам и 7 критериям · Benefit K1–K4 · Cost K5–K7
A3: Этап 1 — Нечёткие веса
A4: Критерий | B4: l | C4: m | D4: u | E4: Тип
A5: K1 — Практическая значимость | B5: =Коллективные!B5 -> 0.9 | C5: =Коллективные!C5 -> 0.9 | D5: =Коллективные!D5 -> 1 | E5: Benefit ↑
A6: K2 — Функциональная содержательность | B6: =Коллективные!B6 -> 0.8 | C6: =Коллективные!C6 -> 0.8 | D6: =Коллективные!D6 -> 0.9 | E6: Benefit ↑
A7: K3 — Потенциал интеграции и развития | B7: =Коллективные!B7 -> 0.7 | C7: =Коллективные!C7 -> 0.8 | D7: =Коллективные!D7 -> 0.8 | E7: Benefit ↑
A8: K4 — Демонстрационная и исследовательская ценность | B8: =Коллективные!B8 -> 0.8 | C8: =Коллективные!C8 -> 0.9 | D8: =Коллективные!D8 -> 0.9 | E8: Benefit ↑
A9: K5 — Трудоёмкость реализации MVP | B9: =Коллективные!B9 -> 0.9 | C9: =Коллективные!C9 -> 0.9 | D9: =Коллективные!D9 -> 1 | E9: Cost ↓
A10: K6 — Зависимость MVP от внешних ресурсов | B10: =Коллективные!B10 -> 0.7 | C10: =Коллективные!C10 -> 0.8 | D10: =Коллективные!D10 -> 0.8 | E10: Cost ↓
A11: K7 — Сложность эксплуатации и сопровождения MVP | B11: =Коллективные!B11 -> 0.7 | C11: =Коллективные!C11 -> 0.7 | D11: =Коллективные!D11 -> 0.8 | E11: Cost ↓
A14: Этап 2 — Нормализованная матрица
A15: Альтернатива | B15: K1 | E15: K2 | H15: K3 | K15: K4 | N15: K5 | Q15: K6 | T15: K7
B16: l | C16: m | D16: u | E16: l | F16: m | G16: u | H16: l | I16: m | J16: u | K16: l | L16: m | M16: u | N16: l | O16: m | P16: u | Q16: l | R16: m | S16: u | T16: l | U16: m | V16: u
A17: A1 — Система управления результатами тестирования на проникновение | B17: =Коллективные!B17/MAX(Коллективные!D17:D20) -> 0.9 | C17: =Коллективные!C17/MAX(Коллективные!D17:D20) -> 0.9 | D17: =Коллективные!D17/MAX(Коллективные!D17:D20) -> 1 | E17: =Коллективные!E17/MAX(Коллективные!G17:G20) -> 0.88888889 | F17: =Коллективные!F17/MAX(Коллективные!G17:G20) -> 0.88888889 | G17: =Коллективные!G17/MAX(Коллективные!G17:G20) -> 1 | H17: =Коллективные!H17/MAX(Коллективные!J17:J20) -> 0.7 | I17: =Коллективные!I17/MAX(Коллективные!J17:J20) -> 0.8 | J17: =Коллективные!J17/MAX(Коллективные!J17:J20) -> 0.8 | K17: =Коллективные!K17/MAX(Коллективные!M17:M20) -> 0.9 | L17: =Коллективные!L17/MAX(Коллективные!M17:M20) -> 0.9 | M17: =Коллективные!M17/MAX(Коллективные!M17:M20) -> 1 | N17: =MIN(Коллективные!N17:N20)/Коллективные!P17 -> 0.66666667 | O17: =MIN(Коллективные!N17:N20)/Коллективные!O17 -> 0.66666667 | P17: =MIN(Коллективные!N17:N20)/Коллективные!N17 -> 0.8 | Q17: =MIN(Коллективные!Q17:Q20)/Коллективные!S17 -> 0.6 | R17: =MIN(Коллективные!Q17:Q20)/Коллективные!R17 -> 0.75 | S17: =MIN(Коллективные!Q17:Q20)/Коллективные!Q17 -> 0.75 | T17: =MIN(Коллективные!T17:T20)/Коллективные!V17 -> 0.8 | U17: =MIN(Коллективные!T17:T20)/Коллективные!U17 -> 0.8 | V17: =MIN(Коллективные!T17:T20)/Коллективные!T17 -> 0.8
A18: A2 — Система контроля безопасности процесса разработки ПО | B18: =Коллективные!B18/MAX(Коллективные!D17:D20) -> 0.9 | C18: =Коллективные!C18/MAX(Коллективные!D17:D20) -> 0.9 | D18: =Коллективные!D18/MAX(Коллективные!D17:D20) -> 1 | E18: =Коллективные!E18/MAX(Коллективные!G17:G20) -> 1 | F18: =Коллективные!F18/MAX(Коллективные!G17:G20) -> 1 | G18: =Коллективные!G18/MAX(Коллективные!G17:G20) -> 1 | H18: =Коллективные!H18/MAX(Коллективные!J17:J20) -> 0.9 | I18: =Коллективные!I18/MAX(Коллективные!J17:J20) -> 1 | J18: =Коллективные!J18/MAX(Коллективные!J17:J20) -> 1 | K18: =Коллективные!K18/MAX(Коллективные!M17:M20) -> 0.8 | L18: =Коллективные!L18/MAX(Коллективные!M17:M20) -> 0.8 | M18: =Коллективные!M18/MAX(Коллективные!M17:M20) -> 0.8 | N18: =MIN(Коллективные!N17:N20)/Коллективные!P18 -> 0.44444444 | O18: =MIN(Коллективные!N17:N20)/Коллективные!O18 -> 0.5 | P18: =MIN(Коллективные!N17:N20)/Коллективные!N18 -> 0.5 | Q18: =MIN(Коллективные!Q17:Q20)/Коллективные!S18 -> 0.375 | R18: =MIN(Коллективные!Q17:Q20)/Коллективные!R18 -> 0.375 | S18: =MIN(Коллективные!Q17:Q20)/Коллективные!Q18 -> 0.42857143 | T18: =MIN(Коллективные!T17:T20)/Коллективные!V18 -> 0.44444444 | U18: =MIN(Коллективные!T17:T20)/Коллективные!U18 -> 0.5 | V18: =MIN(Коллективные!T17:T20)/Коллективные!T18 -> 0.5
A19: A3 — Система регистрации и обработки инцидентов информационной безопасности | B19: =Коллективные!B19/MAX(Коллективные!D17:D20) -> 1 | C19: =Коллективные!C19/MAX(Коллективные!D17:D20) -> 1 | D19: =Коллективные!D19/MAX(Коллективные!D17:D20) -> 1 | E19: =Коллективные!E19/MAX(Коллективные!G17:G20) -> 1 | F19: =Коллективные!F19/MAX(Коллективные!G17:G20) -> 1 | G19: =Коллективные!G19/MAX(Коллективные!G17:G20) -> 1 | H19: =Коллективные!H19/MAX(Коллективные!J17:J20) -> 0.9 | I19: =Коллективные!I19/MAX(Коллективные!J17:J20) -> 0.9 | J19: =Коллективные!J19/MAX(Коллективные!J17:J20) -> 0.9 | K19: =Коллективные!K19/MAX(Коллективные!M17:M20) -> 0.8 | L19: =Коллективные!L19/MAX(Коллективные!M17:M20) -> 0.9 | M19: =Коллективные!M19/MAX(Коллективные!M17:M20) -> 0.9 | N19: =MIN(Коллективные!N17:N20)/Коллективные!P19 -> 0.5 | O19: =MIN(Коллективные!N17:N20)/Коллективные!O19 -> 0.5 | P19: =MIN(Коллективные!N17:N20)/Коллективные!N19 -> 0.57142857 | Q19: =MIN(Коллективные!Q17:Q20)/Коллективные!S19 -> 0.42857143 | R19: =MIN(Коллективные!Q17:Q20)/Коллективные!R19 -> 0.42857143 | S19: =MIN(Коллективные!Q17:Q20)/Коллективные!Q19 -> 0.5 | T19: =MIN(Коллективные!T17:T20)/Коллективные!V19 -> 0.5 | U19: =MIN(Коллективные!T17:T20)/Коллективные!U19 -> 0.5 | V19: =MIN(Коллективные!T17:T20)/Коллективные!T19 -> 0.57142857
A20: A4 — Система управления проверками защищённости информационных систем | B20: =Коллективные!B20/MAX(Коллективные!D17:D20) -> 0.7 | C20: =Коллективные!C20/MAX(Коллективные!D17:D20) -> 0.7 | D20: =Коллективные!D20/MAX(Коллективные!D17:D20) -> 0.8 | E20: =Коллективные!E20/MAX(Коллективные!G17:G20) -> 0.66666667 | F20: =Коллективные!F20/MAX(Коллективные!G17:G20) -> 0.77777778 | G20: =Коллективные!G20/MAX(Коллективные!G17:G20) -> 0.77777778 | H20: =Коллективные!H20/MAX(Коллективные!J17:J20) -> 0.6 | I20: =Коллективные!I20/MAX(Коллективные!J17:J20) -> 0.6 | J20: =Коллективные!J20/MAX(Коллективные!J17:J20) -> 0.7 | K20: =Коллективные!K20/MAX(Коллективные!M17:M20) -> 0.7 | L20: =Коллективные!L20/MAX(Коллективные!M17:M20) -> 0.7 | M20: =Коллективные!M20/MAX(Коллективные!M17:M20) -> 0.8 | N20: =MIN(Коллективные!N17:N20)/Коллективные!P20 -> 0.8 | O20: =MIN(Коллективные!N17:N20)/Коллективные!O20 -> 0.8 | P20: =MIN(Коллективные!N17:N20)/Коллективные!N20 -> 1 | Q20: =MIN(Коллективные!Q17:Q20)/Коллективные!S20 -> 0.75 | R20: =MIN(Коллективные!Q17:Q20)/Коллективные!R20 -> 1 | S20: =MIN(Коллективные!Q17:Q20)/Коллективные!Q20 -> 1 | T20: =MIN(Коллективные!T17:T20)/Коллективные!V20 -> 1 | U20: =MIN(Коллективные!T17:T20)/Коллективные!U20 -> 1 | V20: =MIN(Коллективные!T17:T20)/Коллективные!T20 -> 1
A23: Этап 3 — Взвешенная нормализованная матрица
A24: Альтернатива | B24: K1 | E24: K2 | H24: K3 | K24: K4 | N24: K5 | Q24: K6 | T24: K7
B25: l | C25: m | D25: u | E25: l | F25: m | G25: u | H25: l | I25: m | J25: u | K25: l | L25: m | M25: u | N25: l | O25: m | P25: u | Q25: l | R25: m | S25: u | T25: l | U25: m | V25: u
A26: A1 — Система управления результатами тестирования на проникновение | B26: =B17*$B$5 -> 0.81 | C26: =C17*$C$5 -> 0.81 | D26: =D17*$D$5 -> 1 | E26: =E17*$B$6 -> 0.71111111 | F26: =F17*$C$6 -> 0.71111111 | G26: =G17*$D$6 -> 0.9 | H26: =H17*$B$7 -> 0.49 | I26: =I17*$C$7 -> 0.64 | J26: =J17*$D$7 -> 0.64 | K26: =K17*$B$8 -> 0.72 | L26: =L17*$C$8 -> 0.81 | M26: =M17*$D$8 -> 0.9 | N26: =N17*$B$9 -> 0.6 | O26: =O17*$C$9 -> 0.6 | P26: =P17*$D$9 -> 0.8 | Q26: =Q17*$B$10 -> 0.42 | R26: =R17*$C$10 -> 0.6 | S26: =S17*$D$10 -> 0.6 | T26: =T17*$B$11 -> 0.56 | U26: =U17*$C$11 -> 0.56 | V26: =V17*$D$11 -> 0.64
A27: A2 — Система контроля безопасности процесса разработки ПО | B27: =B18*$B$5 -> 0.81 | C27: =C18*$C$5 -> 0.81 | D27: =D18*$D$5 -> 1 | E27: =E18*$B$6 -> 0.8 | F27: =F18*$C$6 -> 0.8 | G27: =G18*$D$6 -> 0.9 | H27: =H18*$B$7 -> 0.63 | I27: =I18*$C$7 -> 0.8 | J27: =J18*$D$7 -> 0.8 | K27: =K18*$B$8 -> 0.64 | L27: =L18*$C$8 -> 0.72 | M27: =M18*$D$8 -> 0.72 | N27: =N18*$B$9 -> 0.4 | O27: =O18*$C$9 -> 0.45 | P27: =P18*$D$9 -> 0.5 | Q27: =Q18*$B$10 -> 0.2625 | R27: =R18*$C$10 -> 0.3 | S27: =S18*$D$10 -> 0.34285714 | T27: =T18*$B$11 -> 0.31111111 | U27: =U18*$C$11 -> 0.35 | V27: =V18*$D$11 -> 0.4
A28: A3 — Система регистрации и обработки инцидентов информационной безопасности | B28: =B19*$B$5 -> 0.9 | C28: =C19*$C$5 -> 0.9 | D28: =D19*$D$5 -> 1 | E28: =E19*$B$6 -> 0.8 | F28: =F19*$C$6 -> 0.8 | G28: =G19*$D$6 -> 0.9 | H28: =H19*$B$7 -> 0.63 | I28: =I19*$C$7 -> 0.72 | J28: =J19*$D$7 -> 0.72 | K28: =K19*$B$8 -> 0.64 | L28: =L19*$C$8 -> 0.81 | M28: =M19*$D$8 -> 0.81 | N28: =N19*$B$9 -> 0.45 | O28: =O19*$C$9 -> 0.45 | P28: =P19*$D$9 -> 0.57142857 | Q28: =Q19*$B$10 -> 0.3 | R28: =R19*$C$10 -> 0.34285714 | S28: =S19*$D$10 -> 0.4 | T28: =T19*$B$11 -> 0.35 | U28: =U19*$C$11 -> 0.35 | V28: =V19*$D$11 -> 0.45714286
A29: A4 — Система управления проверками защищённости информационных систем | B29: =B20*$B$5 -> 0.63 | C29: =C20*$C$5 -> 0.63 | D29: =D20*$D$5 -> 0.8 | E29: =E20*$B$6 -> 0.53333333 | F29: =F20*$C$6 -> 0.62222222 | G29: =G20*$D$6 -> 0.7 | H29: =H20*$B$7 -> 0.42 | I29: =I20*$C$7 -> 0.48 | J29: =J20*$D$7 -> 0.56 | K29: =K20*$B$8 -> 0.56 | L29: =L20*$C$8 -> 0.63 | M29: =M20*$D$8 -> 0.72 | N29: =N20*$B$9 -> 0.72 | O29: =O20*$C$9 -> 0.72 | P29: =P20*$D$9 -> 1 | Q29: =Q20*$B$10 -> 0.525 | R29: =R20*$C$10 -> 0.8 | S29: =S20*$D$10 -> 0.8 | T29: =T20*$B$11 -> 0.7 | U29: =U20*$C$11 -> 0.7 | V29: =V20*$D$11 -> 0.8
A32: Этап 4 — Идеальное и антиидеальное решения
A33: Решение | B33: K1 | E33: K2 | H33: K3 | K33: K4 | N33: K5 | Q33: K6 | T33: K7
B34: l | C34: m | D34: u | E34: l | F34: m | G34: u | H34: l | I34: m | J34: u | K34: l | L34: m | M34: u | N34: l | O34: m | P34: u | Q34: l | R34: m | S34: u | T34: l | U34: m | V34: u
A35: A+ (идеал) | B35: =MAX(D26:D29) -> 1 | C35: =MAX(D26:D29) -> 1 | D35: =MAX(D26:D29) -> 1 | E35: =MAX(G26:G29) -> 0.9 | F35: =MAX(G26:G29) -> 0.9 | G35: =MAX(G26:G29) -> 0.9 | H35: =MAX(J26:J29) -> 0.8 | I35: =MAX(J26:J29) -> 0.8 | J35: =MAX(J26:J29) -> 0.8 | K35: =MAX(M26:M29) -> 0.9 | L35: =MAX(M26:M29) -> 0.9 | M35: =MAX(M26:M29) -> 0.9 | N35: =MAX(P26:P29) -> 1 | O35: =MAX(P26:P29) -> 1 | P35: =MAX(P26:P29) -> 1 | Q35: =MAX(S26:S29) -> 0.8 | R35: =MAX(S26:S29) -> 0.8 | S35: =MAX(S26:S29) -> 0.8 | T35: =MAX(V26:V29) -> 0.8 | U35: =MAX(V26:V29) -> 0.8 | V35: =MAX(V26:V29) -> 0.8
A36: A− (антиидеал) | B36: =MIN(B26:B29) -> 0.63 | C36: =MIN(B26:B29) -> 0.63 | D36: =MIN(B26:B29) -> 0.63 | E36: =MIN(E26:E29) -> 0.53333333 | F36: =MIN(E26:E29) -> 0.53333333 | G36: =MIN(E26:E29) -> 0.53333333 | H36: =MIN(H26:H29) -> 0.42 | I36: =MIN(H26:H29) -> 0.42 | J36: =MIN(H26:H29) -> 0.42 | K36: =MIN(K26:K29) -> 0.56 | L36: =MIN(K26:K29) -> 0.56 | M36: =MIN(K26:K29) -> 0.56 | N36: =MIN(N26:N29) -> 0.4 | O36: =MIN(N26:N29) -> 0.4 | P36: =MIN(N26:N29) -> 0.4 | Q36: =MIN(Q26:Q29) -> 0.2625 | R36: =MIN(Q26:Q29) -> 0.2625 | S36: =MIN(Q26:Q29) -> 0.2625 | T36: =MIN(T26:T29) -> 0.31111111 | U36: =MIN(T26:T29) -> 0.31111111 | V36: =MIN(T26:T29) -> 0.31111111
A40: Этап 5 — Расстояния и коэффициент близости
A41: Альтернатива | B41: d+ K1 | C41: d+ K2 | D41: d+ K3 | E41: d+ K4 | F41: d+ K5 | G41: d+ K6 | H41: d+ K7 | I41: D+ | J41: d− K1 | K41: d− K2 | L41: d− K3 | M41: d− K4 | N41: d− K5 | O41: d− K6 | P41: d− K7 | Q41: D− | R41: CC | S41: Ранг
A42: A1 — Система управления результатами тестирования на проникновение | B42: =SQRT(((B26-B35)^2+(C26-C35)^2+(D26-D35)^2)/3) -> 0.15513435 | C42: =SQRT(((E26-E35)^2+(F26-F35)^2+(G26-G35)^2)/3) -> 0.15422713 | D42: =SQRT(((H26-H35)^2+(I26-I35)^2+(J26-J35)^2)/3) -> 0.2215852 | E42: =SQRT(((K26-K35)^2+(L26-L35)^2+(M26-M35)^2)/3) -> 0.1161895 | F42: =SQRT(((N26-N35)^2+(O26-O35)^2+(P26-P35)^2)/3) -> 0.34641016 | G42: =SQRT(((Q26-Q35)^2+(R26-R35)^2+(S26-S35)^2)/3) -> 0.27349589 | H42: =SQRT(((T26-T35)^2+(U26-U35)^2+(V26-V35)^2)/3) -> 0.21664102 | I42: =SUM(B42:H42) -> 1.4836833 | J42: =SQRT(((B26-B36)^2+(C26-C36)^2+(D26-D36)^2)/3) -> 0.25929391 | K42: =SQRT(((E26-E36)^2+(F26-F36)^2+(G26-G36)^2)/3) -> 0.25668029 | L42: =SQRT(((H26-H36)^2+(I26-I36)^2+(J26-J36)^2)/3) -> 0.18411953 | M42: =SQRT(((K26-K36)^2+(L26-L36)^2+(M26-M36)^2)/3) -> 0.26057628 | N42: =SQRT(((N26-N36)^2+(O26-O36)^2+(P26-P36)^2)/3) -> 0.28284271 | O42: =SQRT(((Q26-Q36)^2+(R26-R36)^2+(S26-S36)^2)/3) -> 0.29018313 | P42: =SQRT(((T26-T36)^2+(U26-U36)^2+(V26-V36)^2)/3) -> 0.27812423 | Q42: =SUM(J42:P42) -> 1.8118201 | R42: =Q42/(I42+Q42) -> 0.54978554 | S42: =_xlfn.RANK.EQ(R42,$R$42:$R$45,0) -> 1
A43: A2 — Система контроля безопасности процесса разработки ПО | B43: =SQRT(((B27-B35)^2+(C27-C35)^2+(D27-D35)^2)/3) -> 0.15513435 | C43: =SQRT(((E27-E35)^2+(F27-F35)^2+(G27-G35)^2)/3) -> 0.081649658 | D43: =SQRT(((H27-H35)^2+(I27-I35)^2+(J27-J35)^2)/3) -> 0.098149546 | E43: =SQRT(((K27-K35)^2+(L27-L35)^2+(M27-M35)^2)/3) -> 0.21007935 | F43: =SQRT(((N27-N35)^2+(O27-O35)^2+(P27-P35)^2)/3) -> 0.55151307 | G43: =SQRT(((Q27-Q35)^2+(R27-R35)^2+(S27-S35)^2)/3) -> 0.49929478 | H43: =SQRT(((T27-T35)^2+(U27-U35)^2+(V27-V35)^2)/3) -> 0.44777686 | I43: =SUM(B43:H43) -> 2.0435976 | J43: =SQRT(((B27-B36)^2+(C27-C36)^2+(D27-D36)^2)/3) -> 0.25929391 | K43: =SQRT(((E27-E36)^2+(F27-F36)^2+(G27-G36)^2)/3) -> 0.30368112 | L43: =SQRT(((H27-H36)^2+(I27-I36)^2+(J27-J36)^2)/3) -> 0.3331166 | M43: =SQRT(((K27-K36)^2+(L27-L36)^2+(M27-M36)^2)/3) -> 0.13856406 | N43: =SQRT(((N27-N36)^2+(O27-O36)^2+(P27-P36)^2)/3) -> 0.064549722 | O43: =SQRT(((Q27-Q36)^2+(R27-R36)^2+(S27-S36)^2)/3) -> 0.051197397 | P43: =SQRT(((T27-T36)^2+(U27-U36)^2+(V27-V36)^2)/3) -> 0.056016605 | Q43: =SUM(J43:P43) -> 1.2064194 | R43: =Q43/(I43+Q43) -> 0.37120403 | S43: =_xlfn.RANK.EQ(R43,$R$42:$R$45,0) -> 4
A44: A3 — Система регистрации и обработки инцидентов информационной безопасности | B44: =SQRT(((B28-B35)^2+(C28-C35)^2+(D28-D35)^2)/3) -> 0.081649658 | C44: =SQRT(((E28-E35)^2+(F28-F35)^2+(G28-G35)^2)/3) -> 0.081649658 | D44: =SQRT(((H28-H35)^2+(I28-I35)^2+(J28-J35)^2)/3) -> 0.11789826 | E44: =SQRT(((K28-K35)^2+(L28-L35)^2+(M28-M35)^2)/3) -> 0.16713268 | F44: =SQRT(((N28-N35)^2+(O28-O35)^2+(P28-P35)^2)/3) -> 0.51272913 | G44: =SQRT(((Q28-Q35)^2+(R28-R35)^2+(S28-S35)^2)/3) -> 0.4542318 | H44: =SQRT(((T28-T35)^2+(U28-U35)^2+(V28-V35)^2)/3) -> 0.41735318 | I44: =SUM(B44:H44) -> 1.8326444 | J44: =SQRT(((B28-B36)^2+(C28-C36)^2+(D28-D36)^2)/3) -> 0.30697448 | K44: =SQRT(((E28-E36)^2+(F28-F36)^2+(G28-G36)^2)/3) -> 0.30368112 | L44: =SQRT(((H28-H36)^2+(I28-I36)^2+(J28-J36)^2)/3) -> 0.27331301 | M44: =SQRT(((K28-K36)^2+(L28-L36)^2+(M28-M36)^2)/3) -> 0.2092845 | N44: =SQRT(((N28-N36)^2+(O28-O36)^2+(P28-P36)^2)/3) -> 0.10706346 | O44: =SQRT(((Q28-Q36)^2+(R28-R36)^2+(S28-S36)^2)/3) -> 0.094462992 | P44: =SQRT(((T28-T36)^2+(U28-U36)^2+(V28-V36)^2)/3) -> 0.090092475 | Q44: =SUM(J44:P44) -> 1.384872 | R44: =Q44/(I44+Q44) -> 0.43041647 | S44: =_xlfn.RANK.EQ(R44,$R$42:$R$45,0) -> 3
A45: A4 — Система управления проверками защищённости информационных систем | B45: =SQRT(((B29-B35)^2+(C29-C35)^2+(D29-D35)^2)/3) -> 0.32341923 | C45: =SQRT(((E29-E35)^2+(F29-F35)^2+(G29-G35)^2)/3) -> 0.28960026 | D45: =SQRT(((H29-H35)^2+(I29-I35)^2+(J29-J35)^2)/3) -> 0.31853833 | E45: =SQRT(((K29-K35)^2+(L29-L35)^2+(M29-M35)^2)/3) -> 0.27135463 | F45: =SQRT(((N29-N35)^2+(O29-O35)^2+(P29-P35)^2)/3) -> 0.22861904 | G45: =SQRT(((Q29-Q35)^2+(R29-R35)^2+(S29-S35)^2)/3) -> 0.15877132 | H45: =SQRT(((T29-T35)^2+(U29-U35)^2+(V29-V35)^2)/3) -> 0.081649658 | I45: =SUM(B45:H45) -> 1.6719525 | J45: =SQRT(((B29-B36)^2+(C29-C36)^2+(D29-D36)^2)/3) -> 0.098149546 | K45: =SQRT(((E29-E36)^2+(F29-F36)^2+(G29-G36)^2)/3) -> 0.10905505 | L45: =SQRT(((H29-H36)^2+(I29-I36)^2+(J29-J36)^2)/3) -> 0.087939373 | M45: =SQRT(((K29-K36)^2+(L29-L36)^2+(M29-M36)^2)/3) -> 0.10082989 | N45: =SQRT(((N29-N36)^2+(O29-O36)^2+(P29-P36)^2)/3) -> 0.43389707 | O45: =SQRT(((Q29-Q36)^2+(R29-R36)^2+(S29-S36)^2)/3) -> 0.46429831 | P45: =SQRT(((T29-T36)^2+(U29-U36)^2+(V29-V36)^2)/3) -> 0.42484565 | Q45: =SUM(J45:P45) -> 1.7190149 | R45: =Q45/(I45+Q45) -> 0.50693938 | S45: =_xlfn.RANK.EQ(R45,$R$42:$R$45,0) -> 2
A49: Итоговое ранжирование
A50: Место | B50: Код | C50: Концепция | D50: D+ | E50: D− | F50: CC
A51: 1 | B51: A1 | C51: Система управления результатами тестирования на проникновение | D51: =I42 -> 1.4836833 | E51: =Q42 -> 1.8118201 | F51: =R42 -> 0.54978554
A52: 2 | B52: A4 | C52: Система управления проверками защищённости информационных систем | D52: =I45 -> 1.6719525 | E52: =Q45 -> 1.7190149 | F52: =R45 -> 0.50693938
...
