Workbook

Sheet Методика
A1: Фаза 1 — Чёткий коллективный метод анализа иерархий (МАИ)
A3: СТАТУС: расчётный черновик; эксперты ещё не подтвердили прямые попарные сравнения.
A5: Цель, критерии и исходные данные
A7: Концепции | B7: A1 — Pentest; A2 — DevSecOps; A3 — SOC; A4 — Security Audit
A8: Критерии | B8: K1–K4 Benefit (max); K5–K7 Cost (min).
A9: Эксперты | B9: Никита Редин, Павел Шатков, Владислав Полищук.
A10: Исходные баллы | B10: Черновик из expert-assessment/expert-ratings.csv (0–10).
A11: Источник | B11: https://github.com/Redin666/project_management/blob/main/phases/phase-01-concept-selection/expert-assessment/expert-ratings.csv
A12: Ограничение | B12: Матрицы получены из баллов эвристически, не являются независимо полученными суждениями.
A15: Этапы расчёта
A17: 1. При равных исходных баллах a(i,j)=1; иначе сила предпочтения min(9, 1+|xi−xj|).
A18: 2. Для benefit выше лучше, для cost ниже лучше; обратное суждение равно 1/a(i,j).
A19: 3. Эксперт корректирует прямые попарные суждения в жёлтых ячейках индивидуальных листов.
A20: 4. Каждая матрица положительная и обратно-симметричная, диагональ равна единице.
A21: 5. Коллективная матрица равна поэлементному геометрическому среднему трёх матриц экспертов.
A22: 6. Приоритет строки = геометрическое среднее / сумма всех геометрических средних.
A23: 7. λmax ≈ среднее (A·w)i / wi; CI = max(0;(λmax−n)/(n−1)); CR = CI/RI.
A24: 8. RI для матрицы 4×4 = 0,90 и 7×7 = 1,32. Допустимый CR ≤ 0,10.
A25: 9. Общий приоритет = сумма произведений весов критериев на локальные приоритеты альтернатив.
A26: 10. МАИ применяется к тем же 4 альтернативам и 7 критериям, что и TOPSIS.
A27: 11. Итог предварительный, до сбора отдельных попарных экспертных суждений.
... A35: 4. Зафиксируйте экспертное подтверждение матриц перед итоговым выбором концепции.

Sheet Редин
A1: Чёткий МАИ — эксперт Редин
A2: ЧЕРНОВИК: сравнения преобразованы из оценок 0–10; подтвердите или измените жёлтые значения.
A3: Верхний треугольник — ввод; нижний — обратные формулы. Приоритеты и CR вычисляются автоматически.
A7: Этап 1. Веса критериев — матрица 7×7
A8: Элемент | B8: K1 | C8: K2 | D8: K3 | E8: K4 | F8: K5 | G8: K6 | H8: K7 | I8: Средн. геом. | J8: Приоритет | K8: λᵢ
A9: K1 | B9: 1 | C9: 3 | D9: 3 | E9: 2 | F9: 2 | G9: 4 | H9: 4 | I9: =PRODUCT(B9:H9)^(1/7) -> 2.479397 | J9: =I9/SUM($I$9:$I$15) -> 0.30256351 | K9: =(B9*$J$9+C9*$J$10+D9*$J$11+E9*$J$12+F9*$J$13+G9*$J$14+H9*$J$15)/J9 -> 7.0928542
A10: K2 | B10: =1/C9 -> 0.33333333 | C10: 1 | D10: 1 | E10: 0.5 | F10: 0.5 | G10: 2 | H10: 2 | I10: =PRODUCT(B10:H10)^(1/7) -> 0.8547514 | J10: =I10/SUM($I$9:$I$15) -> 0.10430624 | K10: =(B10*$J$9+C10*$J$10+D10*$J$11+E10*$J$12+F10*$J$13+G10*$J$14+H10*$J$15)/J10 -> 7.0357382
A11: K3 | B11: =1/D9 -> 0.33333333 | C11: =1/D10 -> 1 | D11: 1 | E11: 0.5 | F11: 0.5 | G11: 2 | H11: 2 | I11: =PRODUCT(B11:H11)^(1/7) -> 0.8547514 | J11: =I11/SUM($I$9:$I$15) -> 0.10430624 | K11: =(B11*$J$9+C11*$J$10+D11*$J$11+E11*$J$12+F11*$J$13+G11*$J$14+H11*$J$15)/J11 -> 7.0357382
A12: K4 | B12: =1/E9 -> 0.5 | C12: =1/E10 -> 2 | D12: =1/E11 -> 2 | E12: 1 | F12: 1 | G12: 3 | H12: 3 | I12: =PRODUCT(B12:H12)^(1/7) -> 1.5112094 | J12: =I12/SUM($I$9:$I$15) -> 0.18441453 | K12: =(B12*$J$9+C12*$J$10+D12*$J$11+E12*$J$12+F12*$J$13+G12*$J$14+H12*$J$15)/J12 -> 7.0348072
A13: K5 | B13: =1/F9 -> 0.5 | C13: =1/F10 -> 2 | D13: =1/F11 -> 2 | E13: =1/F12 -> 1 | F13: 1 | G13: 3 | H13: 3 | I13: =PRODUCT(B13:H13)^(1/7) -> 1.5112094 | J13: =I13/SUM($I$9:$I$15) -> 0.18441453 | K13: =(B13*$J$9+C13*$J$10+D13*$J$11+E13*$J$12+F13*$J$13+G13*$J$14+H13*$J$15)/J13 -> 7.0348072
A14: K6 | B14: =1/G9 -> 0.25 | C14: =1/G10 -> 0.5 | D14: =1/G11 -> 0.5 | E14: =1/G12 -> 0.33333333 | F14: =1/G13 -> 0.33333333 | G14: 1 | H14: 1 | I14: =PRODUCT(B14:H14)^(1/7) -> 0.49165731 | J14: =I14/SUM($I$9:$I$15) -> 0.059997476 | K14: =(B14*$J$9+C14*$J$10+D14*$J$11+E14*$J$12+F14*$J$13+G14*$J$14+H14*$J$15)/J14 -> 7.0483813
A15: K7 | B15: =1/H9 -> 0.25 | C15: =1/H10 -> 0.5 | D15: =1/H11 -> 0.5 | E15: =1/H12 -> 0.33333333 | F15: =1/H13 -> 0.33333333 | G15: =1/H14 -> 1 | H15: 1 | I15: =PRODUCT(B15:H15)^(1/7) -> 0.49165731 | J15: =I15/SUM($I$9:$I$15) -> 0.059997476 | K15: =(B15*$J$9+C15*$J$10+D15*$J$11+E15*$J$12+F15*$J$13+G15*$J$14+H15*$J$15)/J15 -> 7.0483813
H17: λmax | I17: =AVERAGE(K9:K15) -> 7.047244
H18: CI | I18: =MAX(0,(I17-7)/(7-1)) -> 0.0078739937
H19: RI | I19: 1.32
H20: CR | I20: =I18/I19 -> 0.0059651468 | J20: CR ≤ 0,10 | K20: =IF(I20<=0.1,"OK","ПРОВЕРИТЬ") -> OK
A28: Этап 2. K1 — Практическая значимость | Benefit
A29: Элемент | B29: A1 | C29: A2 | D29: A3 | E29: A4 | I29: Средн. геом. | J29: Приоритет | K29: λᵢ
A30: A1 | B30: 1 | C30: 1 | D30: 0.5 | E30: 3 | I30: =PRODUCT(B30:E30)^(1/4) -> 1.1066819 | J30: =I30/SUM($I$30:$I$33) -> 0.23945798 | K30: =(B30*$J$30+C30*$J$31+D30*$J$32+E30*$J$33)/J30 -> 4.0102839
A31: A2 | B31: =1/C30 -> 1 | C31: 1 | D31: 0.5 | E31: 3 | I31: =PRODUCT(B31:E31)^(1/4) -> 1.1066819 | J31: =I31/SUM($I$30:$I$33) -> 0.23945798 | K31: =(B31*$J$30+C31*$J$31+D31*$J$32+E31*$J$33)/J31 -> 4.0102839
A32: A3 | B32: =1/D30 -> 2 | C32: =1/D31 -> 2 | D32: 1 | E32: 4 | I32: =PRODUCT(B32:E32)^(1/4) -> 2 | J32: =I32/SUM($I$30:$I$33) -> 0.43274943 | K32: =(B32*$J$30+C32*$J$31+D32*$J$32+E32*$J$33)/J32 -> 4.0298604
A33: A4 | B33: =1/E30 -> 0.33333333 | C33: =1/E31 -> 0.33333333 | D33: =1/E32 -> 0.25 | E33: 1 | I33: =PRODUCT(B33:E33)^(1/4) -> 0.40824829 | J33: =I33/SUM($I$30:$I$33) -> 0.088334607 | K33: =(B33*$J$30+C33*$J$31+D33*$J$32+E33*$J$33)/J33 -> 4.0319489
H35: λmax | I35: =AVERAGE(K30:K33) -> 4.0205943
H36: CI | I36: =MAX(0,(I35-4)/(4-1)) -> 0.0068647621
H37: RI | I37: 0.9
H38: CR | I38: =I36/I37 -> 0.0076275135 | J38: CR ≤ 0,10 | K38: =IF(I38<=0.1,"OK","ПРОВЕРИТЬ") -> OK
A43: Этап 3. K2 — Функциональная содержательность | Benefit
A44: Элемент | B44: A1 | C44: A2 | D44: A3 | E44: A4 | I44: Средн. геом. | J44: Приоритет | K44: λᵢ
A45: A1 | B45: 1 | C45: 0.5 | D45: 0.5 | E45: 2 | I45: =PRODUCT(B45:E45)^(1/4) -> 0.84089642 | J45: =I45/SUM($I$45:$I$48) -> 0.18868744 | K45: =(B45*$J$45+C45*$J$46+D45*$J$47+E45*$J$48)/J45 -> 4.0159103
A46: A2 | B46: =1/C45 -> 2 | C46: 1 | D46: 1 | E46: 3 | I46: =PRODUCT(B46:E46)^(1/4) -> 1.5650846 | J46: =I46/SUM($I$45:$I$48) -> 0.3511869 | K46: =(B46*$J$45+C46*$J$46+D46*$J$47+E46*$J$48)/J46 -> 4.0051748
A47: A3 | B47: =1/D45 -> 2 | C47: =1/D46 -> 1 | D47: 1 | E47: 3 | I47: =PRODUCT(B47:E47)^(1/4) -> 1.5650846 | J47: =I47/SUM($I$45:$I$48) -> 0.3511869 | K47: =(B47*$J$45+C47*$J$46+D47*$J$47+E47*$J$48)/J47 -> 4.0051748
A48: A4 | B48: =1/E45 -> 0.5 | C48: =1/E46 -> 0.33333333 | D48: =1/E47 -> 0.33333333 | E48: 1 | I48: =PRODUCT(B48:E48)^(1/4) -> 0.48549177 | J48: =I48/SUM($I$45:$I$48) -> 0.10893875 | K48: =(B48*$J$45+C48*$J$46+D48*$J$47+E48*$J$48)/J48 -> 4.0151653
H50: λmax | I50: =AVERAGE(K45:K48) -> 4.0103563
H51: CI | I51: =MAX(0,(I50-4)/(4-1)) -> 0.0034520922
H52: RI | I52: 0.9
H53: CR | I53: =I51/I52 -> 0.003835658 | J53: CR ≤ 0,10 | K53: =IF(I53<=0.1,"OK","ПРОВЕРИТЬ") -> OK
A58: Этап 4. K3 — Потенциал интеграции и развития | Benefit
A59: Элемент | B59: A1 | C59: A2 | D59: A3 | E59: A4 | I59: Средн. геом. | J59: Приоритет | K59: λᵢ
A60: A1 | B60: 1 | C60: 0.33333333 | D60: 0.5 | E60: 3 | I60: =PRODUCT(B60:E60)^(1/4) -> 0.84089642 | J60: =I60/SUM($I$60:$I$63) -> 0.16971481 | K60: =(B60*$J$60+C60*$J$61+D60*$J$62+E60*$J$63)/J60 -> 4.0504767
A61: A2 | B61: =1/C60 -> 3 | C61: 1 | D61: 2 | E61: 5 | I61: =PRODUCT(B61:E61)^(1/4) -> 2.3403473 | J61: =I61/SUM($I$60:$I$63) -> 0.47234309 | K61: =(B61*$J$60+C61*$J$61+D61*$J$62+E61*$J$63)/J61 -> 4.0540924
...

Sheet Шатков
A1: Чёткий МАИ — эксперт Шатков
A2: ЧЕРНОВИК: сравнения преобразованы из оценок 0–10; подтвердите или измените жёлтые значения.
A3: Верхний треугольник — ввод; нижний — обратные формулы. Приоритеты и CR вычисляются автоматически.
A7: Этап 1. Веса критериев — матрица 7×7
A8: Элемент | B8: K1 | C8: K2 | D8: K3 | E8: K4 | F8: K5 | G8: K6 | H8: K7 | I8: Средн. геом. | J8: Приоритет | K8: λᵢ
A9: K1 | B9: 1 | C9: 2 | D9: 3 | E9: 2 | F9: 0.5 | G9: 2 | H9: 2 | I9: =PRODUCT(B9:H9)^(1/7) -> 1.5746101 | J9: =I9/SUM($I$9:$I$15) -> 0.19714797 | K9: =(B9*$J$9+C9*$J$10+D9*$J$11+E9*$J$12+F9*$J$13+G9*$J$14+H9*$J$15)/J9 -> 7.0423394
A10: K2 | B10: =1/C9 -> 0.5 | C10: 1 | D10: 2 | E10: 1 | F10: 0.33333333 | G10: 1 | H10: 1 | I10: =PRODUCT(B10:H10)^(1/7) -> 0.8547514 | J10: =I10/SUM($I$9:$I$15) -> 0.10701856 | K10: =(B10*$J$9+C10*$J$10+D10*$J$11+E10*$J$12+F10*$J$13+G10*$J$14+H10*$J$15)/J10 -> 7.0084966
A11: K3 | B11: =1/D9 -> 0.33333333 | C11: =1/D10 -> 0.5 | D11: 1 | E11: 0.5 | F11: 0.25 | G11: 0.5 | H11: 0.5 | I11: =PRODUCT(B11:H11)^(1/7) -> 0.47186103 | J11: =I11/SUM($I$9:$I$15) -> 0.059079035 | K11: =(B11*$J$9+C11*$J$10+D11*$J$11+E11*$J$12+F11*$J$13+G11*$J$14+H11*$J$15)/J11 -> 7.0711519
A12: K4 | B12: =1/E9 -> 0.5 | C12: =1/E10 -> 1 | D12: =1/E11 -> 2 | E12: 1 | F12: 0.33333333 | G12: 1 | H12: 1 | I12: =PRODUCT(B12:H12)^(1/7) -> 0.8547514 | J12: =I12/SUM($I$9:$I$15) -> 0.10701856 | K12: =(B12*$J$9+C12*$J$10+D12*$J$11+E12*$J$12+F12*$J$13+G12*$J$14+H12*$J$15)/J12 -> 7.0084966
A13: K5 | B13: =1/F9 -> 2 | C13: =1/F10 -> 3 | D13: =1/F11 -> 4 | E13: =1/F12 -> 3 | F13: 1 | G13: 3 | H13: 3 | I13: =PRODUCT(B13:H13)^(1/7) -> 2.5214686 | J13: =I13/SUM($I$9:$I$15) -> 0.31569875 | K13: =(B13*$J$9+C13*$J$10+D13*$J$11+E13*$J$12+F13*$J$13+G13*$J$14+H13*$J$15)/J13 -> 7.0653862
A14: K6 | B14: =1/G9 -> 0.5 | C14: =1/G10 -> 1 | D14: =1/G11 -> 2 | E14: =1/G12 -> 1 | F14: =1/G13 -> 0.33333333 | G14: 1 | H14: 1 | I14: =PRODUCT(B14:H14)^(1/7) -> 0.8547514 | J14: =I14/SUM($I$9:$I$15) -> 0.10701856 | K14: =(B14*$J$9+C14*$J$10+D14*$J$11+E14*$J$12+F14*$J$13+G14*$J$14+H14*$J$15)/J14 -> 7.0084966
A15: K7 | B15: =1/H9 -> 0.5 | C15: =1/H10 -> 1 | D15: =1/H11 -> 2 | E15: =1/H12 -> 1 | F15: =1/H13 -> 0.33333333 | G15: =1/H14 -> 1 | H15: 1 | I15: =PRODUCT(B15:H15)^(1/7) -> 0.8547514 | J15: =I15/SUM($I$9:$I$15) -> 0.10701856 | K15: =(B15*$J$9+C15*$J$10+D15*$J$11+E15*$J$12+F15*$J$13+G15*$J$14+H15*$J$15)/J15 -> 7.0084966
H17: λmax | I17: =AVERAGE(K9:K15) -> 7.0304091
H18: CI | I18: =MAX(0,(I17-7)/(7-1)) -> 0.0050681853
H19: RI | I19: 1.32
H20: CR | I20: =I18/I19 -> 0.0038395343 | J20: CR ≤ 0,10 | K20: =IF(I20<=0.1,"OK","ПРОВЕРИТЬ") -> OK
A28: Этап 2. K1 — Практическая значимость | Benefit
A29: Элемент | B29: A1 | C29: A2 | D29: A3 | E29: A4 | I29: Средн. геом. | J29: Приоритет | K29: λᵢ
A30: A1 | B30: 1 | C30: 0.5 | D30: 0.5 | E30: 2 | I30: =PRODUCT(B30:E30)^(1/4) -> 0.84089642 | J30: =I30/SUM($I$30:$I$33) -> 0.18868744 | K30: =(B30*$J$30+C30*$J$31+D30*$J$32+E30*$J$33)/J30 -> 4.0159103
A31: A2 | B31: =1/C30 -> 2 | C31: 1 | D31: 1 | E31: 3 | I31: =PRODUCT(B31:E31)^(1/4) -> 1.5650846 | J31: =I31/SUM($I$30:$I$33) -> 0.3511869 | K31: =(B31*$J$30+C31*$J$31+D31*$J$32+E31*$J$33)/J31 -> 4.0051748
A32: A3 | B32: =1/D30 -> 2 | C32: =1/D31 -> 1 | D32: 1 | E32: 3 | I32: =PRODUCT(B32:E32)^(1/4) -> 1.5650846 | J32: =I32/SUM($I$30:$I$33) -> 0.3511869 | K32: =(B32*$J$30+C32*$J$31+D32*$J$32+E32*$J$33)/J32 -> 4.0051748
A33: A4 | B33: =1/E30 -> 0.5 | C33: =1/E31 -> 0.33333333 | D33: =1/E32 -> 0.33333333 | E33: 1 | I33: =PRODUCT(B33:E33)^(1/4) -> 0.48549177 | J33: =I33/SUM($I$30:$I$33) -> 0.10893875 | K33: =(B33*$J$30+C33*$J$31+D33*$J$32+E33*$J$33)/J33 -> 4.0151653
H35: λmax | I35: =AVERAGE(K30:K33) -> 4.0103563
H36: CI | I36: =MAX(0,(I35-4)/(4-1)) -> 0.0034520922
H37: RI | I37: 0.9
H38: CR | I38: =I36/I37 -> 0.003835658 | J38: CR ≤ 0,10 | K38: =IF(I38<=0.1,"OK","ПРОВЕРИТЬ") -> OK
A43: Этап 3. K2 — Функциональная содержательность | Benefit
A44: Элемент | B44: A1 | C44: A2 | D44: A3 | E44: A4 | I44: Средн. геом. | J44: Приоритет | K44: λᵢ
A45: A1 | B45: 1 | C45: 0.5 | D45: 0.5 | E45: 3 | I45: =PRODUCT(B45:E45)^(1/4) -> 0.93060486 | J45: =I45/SUM($I$45:$I$48) -> 0.19909784 | K45: =(B45*$J$45+C45*$J$46+D45*$J$47+E45*$J$48)/J45 -> 4.0319489
A46: A2 | B46: =1/C45 -> 2 | C46: 1 | D46: 1 | E46: 4 | I46: =PRODUCT(B46:E46)^(1/4) -> 1.6817928 | J46: =I46/SUM($I$45:$I$48) -> 0.35981041 | K46: =(B46*$J$45+C46*$J$46+D46*$J$47+E46*$J$48)/J46 -> 4.0102839
A47: A3 | B47: =1/D45 -> 2 | C47: =1/D46 -> 1 | D47: 1 | E47: 4 | I47: =PRODUCT(B47:E47)^(1/4) -> 1.6817928 | J47: =I47/SUM($I$45:$I$48) -> 0.35981041 | K47: =(B47*$J$45+C47*$J$46+D47*$J$47+E47*$J$48)/J47 -> 4.0102839
A48: A4 | B48: =1/E45 -> 0.33333333 | C48: =1/E46 -> 0.25 | D48: =1/E47 -> 0.25 | E48: 1 | I48: =PRODUCT(B48:E48)^(1/4) -> 0.37991784 | J48: =I48/SUM($I$45:$I$48) -> 0.081281351 | K48: =(B48*$J$45+C48*$J$46+D48*$J$47+E48*$J$48)/J48 -> 4.0298604
H50: λmax | I50: =AVERAGE(K45:K48) -> 4.0205943
H51: CI | I51: =MAX(0,(I50-4)/(4-1)) -> 0.0068647621
H52: RI | I52: 0.9
H53: CR | I53: =I51/I52 -> 0.0076275135 | J53: CR ≤ 0,10 | K53: =IF(I53<=0.1,"OK","ПРОВЕРИТЬ") -> OK
A58: Этап 4. K3 — Потенциал интеграции и развития | Benefit
A59: Элемент | B59: A1 | C59: A2 | D59: A3 | E59: A4 | I59: Средн. геом. | J59: Приоритет | K59: λᵢ
A60: A1 | B60: 1 | C60: 0.33333333 | D60: 0.33333333 | E60: 2 | I60: =PRODUCT(B60:E60)^(1/4) -> 0.68658905 | J60: =I60/SUM($I$60:$I$63) -> 0.14216693 | K60: =(B60*$J$60+C60*$J$61+D60*$J$62+E60*$J$63)/J60 -> 4.0319489
A61: A2 | B61: =1/C60 -> 3 | C61: 1 | D61: 1 | E61: 4 | I61: =PRODUCT(B61:E61)^(1/4) -> 1.8612097 | J61: =I61/SUM($I$60:$I$63) -> 0.38538698 | K61: =(B61*$J$60+C61*$J$61+D61*$J$62+E61*$J$63)/J61 -> 4.0102839
...

Sheet Полищук
A1: Чёткий МАИ — эксперт Полищук
A2: ЧЕРНОВИК: сравнения преобразованы из оценок 0–10; подтвердите или измените жёлтые значения.
A3: Верхний треугольник — ввод; нижний — обратные формулы. Приоритеты и CR вычисляются автоматически.
A7: Этап 1. Веса критериев — матрица 7×7
A8: Элемент | B8: K1 | C8: K2 | D8: K3 | E8: K4 | F8: K5 | G8: K6 | H8: K7 | I8: Средн. геом. | J8: Приоритет | K8: λᵢ
A9: K1 | B9: 1 | C9: 1 | D9: 2 | E9: 1 | F9: 1 | G9: 2 | H9: 3 | I9: =PRODUCT(B9:H9)^(1/7) -> 1.4261616 | J9: =I9/SUM($I$9:$I$15) -> 0.18695138 | K9: =(B9*$J$9+C9*$J$10+D9*$J$11+E9*$J$12+F9*$J$13+G9*$J$14+H9*$J$15)/J9 -> 7.0049997
A10: K2 | B10: =1/C9 -> 1 | C10: 1 | D10: 2 | E10: 1 | F10: 1 | G10: 2 | H10: 3 | I10: =PRODUCT(B10:H10)^(1/7) -> 1.4261616 | J10: =I10/SUM($I$9:$I$15) -> 0.18695138 | K10: =(B10*$J$9+C10*$J$10+D10*$J$11+E10*$J$12+F10*$J$13+G10*$J$14+H10*$J$15)/J10 -> 7.0049997
A11: K3 | B11: =1/D9 -> 0.5 | C11: =1/D10 -> 0.5 | D11: 1 | E11: 0.5 | F11: 0.5 | G11: 1 | H11: 2 | I11: =PRODUCT(B11:H11)^(1/7) -> 0.74299714 | J11: =I11/SUM($I$9:$I$15) -> 0.097397332 | K11: =(B11*$J$9+C11*$J$10+D11*$J$11+E11*$J$12+F11*$J$13+G11*$J$14+H11*$J$15)/J11 -> 7.0176161
A12: K4 | B12: =1/E9 -> 1 | C12: =1/E10 -> 1 | D12: =1/E11 -> 2 | E12: 1 | F12: 1 | G12: 2 | H12: 3 | I12: =PRODUCT(B12:H12)^(1/7) -> 1.4261616 | J12: =I12/SUM($I$9:$I$15) -> 0.18695138 | K12: =(B12*$J$9+C12*$J$10+D12*$J$11+E12*$J$12+F12*$J$13+G12*$J$14+H12*$J$15)/J12 -> 7.0049997
A13: K5 | B13: =1/F9 -> 1 | C13: =1/F10 -> 1 | D13: =1/F11 -> 2 | E13: =1/F12 -> 1 | F13: 1 | G13: 2 | H13: 3 | I13: =PRODUCT(B13:H13)^(1/7) -> 1.4261616 | J13: =I13/SUM($I$9:$I$15) -> 0.18695138 | K13: =(B13*$J$9+C13*$J$10+D13*$J$11+E13*$J$12+F13*$J$13+G13*$J$14+H13*$J$15)/J13 -> 7.0049997
A14: K6 | B14: =1/G9 -> 0.5 | C14: =1/G10 -> 0.5 | D14: =1/G11 -> 1 | E14: =1/G12 -> 0.5 | F14: =1/G13 -> 0.5 | G14: 1 | H14: 2 | I14: =PRODUCT(B14:H14)^(1/7) -> 0.74299714 | J14: =I14/SUM($I$9:$I$15) -> 0.097397332 | K14: =(B14*$J$9+C14*$J$10+D14*$J$11+E14*$J$12+F14*$J$13+G14*$J$14+H14*$J$15)/J14 -> 7.0176161
A15: K7 | B15: =1/H9 -> 0.33333333 | C15: =1/H10 -> 0.33333333 | D15: =1/H11 -> 0.5 | E15: =1/H12 -> 0.33333333 | F15: =1/H13 -> 0.33333333 | G15: =1/H14 -> 0.5 | H15: 1 | I15: =PRODUCT(B15:H15)^(1/7) -> 0.43787557 | J15: =I15/SUM($I$9:$I$15) -> 0.057399833 | K15: =(B15*$J$9+C15*$J$10+D15*$J$11+E15*$J$12+F15*$J$13+G15*$J$14+H15*$J$15)/J15 -> 7.039492
H17: λmax | I17: =AVERAGE(K9:K15) -> 7.0135318
H18: CI | I18: =MAX(0,(I17-7)/(7-1)) -> 0.0022553075
H19: RI | I19: 1.32
H20: CR | I20: =I18/I19 -> 0.0017085663 | J20: CR ≤ 0,10 | K20: =IF(I20<=0.1,"OK","ПРОВЕРИТЬ") -> OK
A28: Этап 2. K1 — Практическая значимость | Benefit
A29: Элемент | B29: A1 | C29: A2 | D29: A3 | E29: A4 | I29: Средн. геом. | J29: Приоритет | K29: λᵢ
A30: A1 | B30: 1 | C30: 2 | D30: 1 | E30: 4 | I30: =PRODUCT(B30:E30)^(1/4) -> 1.6817928 | J30: =I30/SUM($I$30:$I$33) -> 0.35981041 | K30: =(B30*$J$30+C30*$J$31+D30*$J$32+E30*$J$33)/J30 -> 4.0102839
A31: A2 | B31: =1/C30 -> 0.5 | C31: 1 | D31: 0.5 | E31: 3 | I31: =PRODUCT(B31:E31)^(1/4) -> 0.93060486 | J31: =I31/SUM($I$30:$I$33) -> 0.19909784 | K31: =(B31*$J$30+C31*$J$31+D31*$J$32+E31*$J$33)/J31 -> 4.0319489
A32: A3 | B32: =1/D30 -> 1 | C32: =1/D31 -> 2 | D32: 1 | E32: 4 | I32: =PRODUCT(B32:E32)^(1/4) -> 1.6817928 | J32: =I32/SUM($I$30:$I$33) -> 0.35981041 | K32: =(B32*$J$30+C32*$J$31+D32*$J$32+E32*$J$33)/J32 -> 4.0102839
A33: A4 | B33: =1/E30 -> 0.25 | C33: =1/E31 -> 0.33333333 | D33: =1/E32 -> 0.25 | E33: 1 | I33: =PRODUCT(B33:E33)^(1/4) -> 0.37991784 | J33: =I33/SUM($I$30:$I$33) -> 0.081281351 | K33: =(B33*$J$30+C33*$J$31+D33*$J$32+E33*$J$33)/J33 -> 4.0298604
H35: λmax | I35: =AVERAGE(K30:K33) -> 4.0205943
H36: CI | I36: =MAX(0,(I35-4)/(4-1)) -> 0.0068647621
H37: RI | I37: 0.9
H38: CR | I38: =I36/I37 -> 0.0076275135 | J38: CR ≤ 0,10 | K38: =IF(I38<=0.1,"OK","ПРОВЕРИТЬ") -> OK
A43: Этап 3. K2 — Функциональная содержательность | Benefit
A44: Элемент | B44: A1 | C44: A2 | D44: A3 | E44: A4 | I44: Средн. геом. | J44: Приоритет | K44: λᵢ
A45: A1 | B45: 1 | C45: 1 | D45: 1 | E45: 3 | I45: =PRODUCT(B45:E45)^(1/4) -> 1.316074 | J45: =I45/SUM($I$45:$I$48) -> 0.3 | K45: =(B45*$J$45+C45*$J$46+D45*$J$47+E45*$J$48)/J45 -> 4
A46: A2 | B46: =1/C45 -> 1 | C46: 1 | D46: 1 | E46: 3 | I46: =PRODUCT(B46:E46)^(1/4) -> 1.316074 | J46: =I46/SUM($I$45:$I$48) -> 0.3 | K46: =(B46*$J$45+C46*$J$46+D46*$J$47+E46*$J$48)/J46 -> 4
A47: A3 | B47: =1/D45 -> 1 | C47: =1/D46 -> 1 | D47: 1 | E47: 3 | I47: =PRODUCT(B47:E47)^(1/4) -> 1.316074 | J47: =I47/SUM($I$45:$I$48) -> 0.3 | K47: =(B47*$J$45+C47*$J$46+D47*$J$47+E47*$J$48)/J47 -> 4
A48: A4 | B48: =1/E45 -> 0.33333333 | C48: =1/E46 -> 0.33333333 | D48: =1/E47 -> 0.33333333 | E48: 1 | I48: =PRODUCT(B48:E48)^(1/4) -> 0.43869134 | J48: =I48/SUM($I$45:$I$48) -> 0.1 | K48: =(B48*$J$45+C48*$J$46+D48*$J$47+E48*$J$48)/J48 -> 4
H50: λmax | I50: =AVERAGE(K45:K48) -> 4
H51: CI | I51: =MAX(0,(I50-4)/(4-1)) -> 0
H52: RI | I52: 0.9
H53: CR | I53: =I51/I52 -> 0 | J53: CR ≤ 0,10 | K53: =IF(I53<=0.1,"OK","ПРОВЕРИТЬ") -> OK
A58: Этап 4. K3 — Потенциал интеграции и развития | Benefit
A59: Элемент | B59: A1 | C59: A2 | D59: A3 | E59: A4 | I59: Средн. геом. | J59: Приоритет | K59: λᵢ
A60: A1 | B60: 1 | C60: 0.33333333 | D60: 0.5 | E60: 2 | I60: =PRODUCT(B60:E60)^(1/4) -> 0.75983569 | J60: =I60/SUM($I$60:$I$63) -> 0.16026656 | K60: =(B60*$J$60+C60*$J$61+D60*$J$62+E60*$J$63)/J60 -> 4.0262161
A61: A2 | B61: =1/C60 -> 3 | C61: 1 | D61: 2 | E61: 4 | I61: =PRODUCT(B61:E61)^(1/4) -> 2.2133638 | J61: =I61/SUM($I$60:$I$63) -> 0.46684856 | K61: =(B61*$J$60+C61*$J$61+D61*$J$62+E61*$J$63)/J61 -> 4.0355873
...

Sheet Коллективный
A1: Фаза 1 — Чёткий коллективный МАИ
A2: Геометрическое среднее попарных сравнений трёх экспертов; Cost учтены обратным предпочтением.
A3: Локальные приоритеты и CR вычисляются из агрегированных матриц.
A7: Этап 1. Веса критериев — матрица 7×7
A8: Элемент | B8: K1 | C8: K2 | D8: K3 | E8: K4 | F8: K5 | G8: K6 | H8: K7 | I8: Средн. геом. | J8: Приоритет | K8: λᵢ
A9: K1 | B9: =('Редин'!B9*'Шатков'!B9*'Полищук'!B9)^(1/3) -> 1 | C9: =('Редин'!C9*'Шатков'!C9*'Полищук'!C9)^(1/3) -> 1.8171206 | D9: =('Редин'!D9*'Шатков'!D9*'Полищук'!D9)^(1/3) -> 2.6207414 | E9: =('Редин'!E9*'Шатков'!E9*'Полищук'!E9)^(1/3) -> 1.5874011 | F9: =('Редин'!F9*'Шатков'!F9*'Полищук'!F9)^(1/3) -> 1 | G9: =('Редин'!G9*'Шатков'!G9*'Полищук'!G9)^(1/3) -> 2.5198421 | H9: =('Редин'!H9*'Шатков'!H9*'Полищук'!H9)^(1/3) -> 2.8844991 | I9: =PRODUCT(B9:H9)^(1/7) -> 1.7724036 | J9: =I9/SUM($I$9:$I$15) -> 0.23058414 | K9: =(B9*$J$9+C9*$J$10+D9*$J$11+E9*$J$12+F9*$J$13+G9*$J$14+H9*$J$15)/J9 -> 7.0088977
A10: K2 | B10: =('Редин'!B10*'Шатков'!B10*'Полищук'!B10)^(1/3) -> 0.55032121 | C10: =('Редин'!C10*'Шатков'!C10*'Полищук'!C10)^(1/3) -> 1 | D10: =('Редин'!D10*'Шатков'!D10*'Полищук'!D10)^(1/3) -> 1.5874011 | E10: =('Редин'!E10*'Шатков'!E10*'Полищук'!E10)^(1/3) -> 0.79370053 | F10: =('Редин'!F10*'Шатков'!F10*'Полищук'!F10)^(1/3) -> 0.55032121 | G10: =('Редин'!G10*'Шатков'!G10*'Полищук'!G10)^(1/3) -> 1.5874011 | H10: =('Редин'!H10*'Шатков'!H10*'Полищук'!H10)^(1/3) -> 1.8171206 | I10: =PRODUCT(B10:H10)^(1/7) -> 1.0137934 | J10: =I10/SUM($I$9:$I$15) -> 0.13189134 | K10: =(B10*$J$9+C10*$J$10+D10*$J$11+E10*$J$12+F10*$J$13+G10*$J$14+H10*$J$15)/J10 -> 7.0058003
A11: K3 | B11: =('Редин'!B11*'Шатков'!B11*'Полищук'!B11)^(1/3) -> 0.38157141 | C11: =('Редин'!C11*'Шатков'!C11*'Полищук'!C11)^(1/3) -> 0.62996052 | D11: =('Редин'!D11*'Шатков'!D11*'Полищук'!D11)^(1/3) -> 1 | E11: =('Редин'!E11*'Шатков'!E11*'Полищук'!E11)^(1/3) -> 0.5 | F11: =('Редин'!F11*'Шатков'!F11*'Полищук'!F11)^(1/3) -> 0.39685026 | G11: =('Редин'!G11*'Шатков'!G11*'Полищук'!G11)^(1/3) -> 1 | H11: =('Редин'!H11*'Шатков'!H11*'Полищук'!H11)^(1/3) -> 1.259921 | I11: =PRODUCT(B11:H11)^(1/7) -> 0.66918628 | J11: =I11/SUM($I$9:$I$15) -> 0.087059034 | K11: =(B11*$J$9+C11*$J$10+D11*$J$11+E11*$J$12+F11*$J$13+G11*$J$14+H11*$J$15)/J11 -> 7.0082524
A12: K4 | B12: =('Редин'!B12*'Шатков'!B12*'Полищук'!B12)^(1/3) -> 0.62996052 | C12: =('Редин'!C12*'Шатков'!C12*'Полищук'!C12)^(1/3) -> 1.259921 | D12: =('Редин'!D12*'Шатков'!D12*'Полищук'!D12)^(1/3) -> 2 | E12: =('Редин'!E12*'Шатков'!E12*'Полищук'!E12)^(1/3) -> 1 | F12: =('Редин'!F12*'Шатков'!F12*'Полищук'!F12)^(1/3) -> 0.69336127 | G12: =('Редин'!G12*'Шатков'!G12*'Полищук'!G12)^(1/3) -> 1.8171206 | H12: =('Редин'!H12*'Шатков'!H12*'Полищук'!H12)^(1/3) -> 2.0800838 | I12: =PRODUCT(B12:H12)^(1/7) -> 1.22587 | J12: =I12/SUM($I$9:$I$15) -> 0.15948183 | K12: =(B12*$J$9+C12*$J$10+D12*$J$11+E12*$J$12+F12*$J$13+G12*$J$14+H12*$J$15)/J12 -> 7.0097103
A13: K5 | B13: =('Редин'!B13*'Шатков'!B13*'Полищук'!B13)^(1/3) -> 1 | C13: =('Редин'!C13*'Шатков'!C13*'Полищук'!C13)^(1/3) -> 1.8171206 | D13: =('Редин'!D13*'Шатков'!D13*'Полищук'!D13)^(1/3) -> 2.5198421 | E13: =('Редин'!E13*'Шатков'!E13*'Полищук'!E13)^(1/3) -> 1.4422496 | F13: =('Редин'!F13*'Шатков'!F13*'Полищук'!F13)^(1/3) -> 1 | G13: =('Редин'!G13*'Шатков'!G13*'Полищук'!G13)^(1/3) -> 2.6207414 | H13: =('Редин'!H13*'Шатков'!H13*'Полищук'!H13)^(1/3) -> 3 | I13: =PRODUCT(B13:H13)^(1/7) -> 1.7581219 | J13: =I13/SUM($I$9:$I$15) -> 0.22872614 | K13: =(B13*$J$9+C13*$J$10+D13*$J$11+E13*$J$12+F13*$J$13+G13*$J$14+H13*$J$15)/J13 -> 7.0025209
A14: K6 | B14: =('Редин'!B14*'Шатков'!B14*'Полищук'!B14)^(1/3) -> 0.39685026 | C14: =('Редин'!C14*'Шатков'!C14*'Полищук'!C14)^(1/3) -> 0.62996052 | D14: =('Редин'!D14*'Шатков'!D14*'Полищук'!D14)^(1/3) -> 1 | E14: =('Редин'!E14*'Шатков'!E14*'Полищук'!E14)^(1/3) -> 0.55032121 | F14: =('Редин'!F14*'Шатков'!F14*'Полищук'!F14)^(1/3) -> 0.38157141 | G14: =('Редин'!G14*'Шатков'!G14*'Полищук'!G14)^(1/3) -> 1 | H14: =('Редин'!H14*'Шатков'!H14*'Полищук'!H14)^(1/3) -> 1.259921 | I14: =PRODUCT(B14:H14)^(1/7) -> 0.67841664 | J14: =I14/SUM($I$9:$I$15) -> 0.088259875 | K14: =(B14*$J$9+C14*$J$10+D14*$J$11+E14*$J$12+F14*$J$13+G14*$J$14+H14*$J$15)/J14 -> 7.0041499
A15: K7 | B15: =('Редин'!B15*'Шатков'!B15*'Полищук'!B15)^(1/3) -> 0.34668064 | C15: =('Редин'!C15*'Шатков'!C15*'Полищук'!C15)^(1/3) -> 0.55032121 | D15: =('Редин'!D15*'Шатков'!D15*'Полищук'!D15)^(1/3) -> 0.79370053 | E15: =('Редин'!E15*'Шатков'!E15*'Полищук'!E15)^(1/3) -> 0.48074986 | F15: =('Редин'!F15*'Шатков'!F15*'Полищук'!F15)^(1/3) -> 0.33333333 | G15: =('Редин'!G15*'Шатков'!G15*'Полищук'!G15)^(1/3) -> 0.79370053 | H15: =('Редин'!H15*'Шатков'!H15*'Полищук'!H15)^(1/3) -> 1 | I15: =PRODUCT(B15:H15)^(1/7) -> 0.56878877 | J15: =I15/SUM($I$9:$I$15) -> 0.073997633 | K15: =(B15*$J$9+C15*$J$10+D15*$J$11+E15*$J$12+F15*$J$13+G15*$J$14+H15*$J$15)/J15 -> 7.0081014
H17: λmax | I17: =AVERAGE(K9:K15) -> 7.0067761
H18: CI | I18: =MAX(0,(I17-7)/(7-1)) -> 0.001129354
H19: RI | I19: 1.32
H20: CR | I20: =I18/I19 -> 0.00085557124 | J20: CR ≤ 0,10 | K20: =IF(I20<=0.1,"OK","ПРОВЕРИТЬ") -> OK
A28: Этап 2. K1 — Практическая значимость | Benefit
A29: Элемент | B29: A1 | C29: A2 | D29: A3 | E29: A4 | I29: Средн. геом. | J29: Приоритет | K29: λᵢ
A30: A1 | B30: =('Редин'!B30*'Шатков'!B30*'Полищук'!B30)^(1/3) -> 1 | C30: =('Редин'!C30*'Шатков'!C30*'Полищук'!C30)^(1/3) -> 1 | D30: =('Редин'!D30*'Шатков'!D30*'Полищук'!D30)^(1/3) -> 0.62996052 | E30: =('Редин'!E30*'Шатков'!E30*'Полищук'!E30)^(1/3) -> 2.8844991 | I30: =PRODUCT(B30:E30)^(1/4) -> 1.1610367 | J30: =I30/SUM($I$30:$I$33) -> 0.25827256 | K30: =(B30*$J$30+C30*$J$31+D30*$J$32+E30*$J$33)/J30 -> 4.002853
A31: A2 | B31: =('Редин'!B31*'Шатков'!B31*'Полищук'!B31)^(1/3) -> 1 | C31: =('Редин'!C31*'Шатков'!C31*'Полищук'!C31)^(1/3) -> 1 | D31: =('Редин'!D31*'Шатков'!D31*'Полищук'!D31)^(1/3) -> 0.62996052 | E31: =('Редин'!E31*'Шатков'!E31*'Полищук'!E31)^(1/3) -> 3 | I31: =PRODUCT(B31:E31)^(1/4) -> 1.1724887 | J31: =I31/SUM($I$30:$I$33) -> 0.26082006 | K31: =(B31*$J$30+C31*$J$31+D31*$J$32+E31*$J$33)/J31 -> 4.0053544
A32: A3 | B32: =('Редин'!B32*'Шатков'!B32*'Полищук'!B32)^(1/3) -> 1.5874011 | C32: =('Редин'!C32*'Шатков'!C32*'Полищук'!C32)^(1/3) -> 1.5874011 | D32: =('Редин'!D32*'Шатков'!D32*'Полищук'!D32)^(1/3) -> 1 | E32: =('Редин'!E32*'Шатков'!E32*'Полищук'!E32)^(1/3) -> 3.6342412 | I32: =PRODUCT(B32:E32)^(1/4) -> 1.7395895 | J32: =I32/SUM($I$30:$I$33) -> 0.38697161 | K32: =(B32*$J$30+C32*$J$31+D32*$J$32+E32*$J$33)/J32 -> 4.0115734
A33: A4 | B33: =('Редин'!B33*'Шатков'!B33*'Полищук'!B33)^(1/3) -> 0.34668064 | C33: =('Редин'!C33*'Шатков'!C33*'Полищук'!C33)^(1/3) -> 0.33333333 | D33: =('Редин'!D33*'Шатков'!D33*'Полищук'!D33)^(1/3) -> 0.2751606 | E33: =('Редин'!E33*'Шатков'!E33*'Полищук'!E33)^(1/3) -> 1 | I33: =PRODUCT(B33:E33)^(1/4) -> 0.42227819 | J33: =I33/SUM($I$30:$I$33) -> 0.093935767 | K33: =(B33*$J$30+C33*$J$31+D33*$J$32+E33*$J$33)/J33 -> 4.0122441
H35: λmax | I35: =AVERAGE(K30:K33) -> 4.0080062
H36: CI | I36: =MAX(0,(I35-4)/(4-1)) -> 0.0026687361
H37: RI | I37: 0.9
H38: CR | I38: =I36/I37 -> 0.0029652623 | J38: CR ≤ 0,10 | K38: =IF(I38<=0.1,"OK","ПРОВЕРИТЬ") -> OK
A43: Этап 3. K2 — Функциональная содержательность | Benefit
A44: Элемент | B44: A1 | C44: A2 | D44: A3 | E44: A4 | I44: Средн. геом. | J44: Приоритет | K44: λᵢ
A45: A1 | B45: =('Редин'!B45*'Шатков'!B45*'Полищук'!B45)^(1/3) -> 1 | C45: =('Редин'!C45*'Шатков'!C45*'Полищук'!C45)^(1/3) -> 0.62996052 | D45: =('Редин'!D45*'Шатков'!D45*'Полищук'!D45)^(1/3) -> 0.62996052 | E45: =('Редин'!E45*'Шатков'!E45*'Полищук'!E45)^(1/3) -> 2.6207414 | I45: =PRODUCT(B45:E45)^(1/4) -> 1.0098636 | J45: =I45/SUM($I$45:$I$48) -> 0.22599311 | K45: =(B45*$J$45+C45*$J$46+D45*$J$47+E45*$J$48)/J45 -> 4.0102107
A46: A2 | B46: =('Редин'!B46*'Шатков'!B46*'Полищук'!B46)^(1/3) -> 1.5874011 | C46: =('Редин'!C46*'Шатков'!C46*'Полищук'!C46)^(1/3) -> 1 | D46: =('Редин'!D46*'Шатков'!D46*'Полищук'!D46)^(1/3) -> 1 | E46: =('Редин'!E46*'Шатков'!E46*'Полищук'!E46)^(1/3) -> 3.3019272 | I46: =PRODUCT(B46:E46)^(1/4) -> 1.5130857 | J46: =I46/SUM($I$45:$I$48) -> 0.33860708 | K46: =(B46*$J$45+C46*$J$46+D46*$J$47+E46*$J$48)/J46 -> 4.0033374
A47: A3 | B47: =('Редин'!B47*'Шатков'!B47*'Полищук'!B47)^(1/3) -> 1.5874011 | C47: =('Редин'!C47*'Шатков'!C47*'Полищук'!C47)^(1/3) -> 1 | D47: =('Редин'!D47*'Шатков'!D47*'Полищук'!D47)^(1/3) -> 1 | E47: =('Редин'!E47*'Шатков'!E47*'Полищук'!E47)^(1/3) -> 3.3019272 | I47: =PRODUCT(B47:E47)^(1/4) -> 1.5130857 | J47: =I47/SUM($I$45:$I$48) -> 0.33860708 | K47: =(B47*$J$45+C47*$J$46+D47*$J$47+E47*$J$48)/J47 -> 4.0033374
A48: A4 | B48: =('Редин'!B48*'Шатков'!B48*'Полищук'!B48)^(1/3) -> 0.38157141 | C48: =('Редин'!C48*'Шатков'!C48*'Полищук'!C48)^(1/3) -> 0.30285343 | D48: =('Редин'!D48*'Шатков'!D48*'Полищук'!D48)^(1/3) -> 0.30285343 | E48: =('Редин'!E48*'Шатков'!E48*'Полищук'!E48)^(1/3) -> 1 | I48: =PRODUCT(B48:E48)^(1/4) -> 0.432524 | J48: =I48/SUM($I$45:$I$48) -> 0.096792722 | K48: =(B48*$J$45+C48*$J$46+D48*$J$47+E48*$J$48)/J48 -> 4.0098249
H50: λmax | I50: =AVERAGE(K45:K48) -> 4.0066776
H51: CI | I51: =MAX(0,(I50-4)/(4-1)) -> 0.0022258662
H52: RI | I52: 0.9
H53: CR | I53: =I51/I52 -> 0.0024731847 | J53: CR ≤ 0,10 | K53: =IF(I53<=0.1,"OK","ПРОВЕРИТЬ") -> OK
A58: Этап 4. K3 — Потенциал интеграции и развития | Benefit
A59: Элемент | B59: A1 | C59: A2 | D59: A3 | E59: A4 | I59: Средн. геом. | J59: Приоритет | K59: λᵢ
A60: A1 | B60: =('Редин'!B60*'Шатков'!B60*'Полищук'!B60)^(1/3) -> 1 | C60: =('Редин'!C60*'Шатков'!C60*'Полищук'!C60)^(1/3) -> 0.33333333 | D60: =('Редин'!D60*'Шатков'!D60*'Полищук'!D60)^(1/3) -> 0.43679023 | E60: =('Редин'!E60*'Шатков'!E60*'Полищук'!E60)^(1/3) -> 2.2894285 | I60: =PRODUCT(B60:E60)^(1/4) -> 0.75983569 | J60: =I60/SUM($I$60:$I$63) -> 0.15797192 | K60: =(B60*$J$60+C60*$J$61+D60*$J$62+E60*$J$63)/J60 -> 4.0348325
A61: A2 | B61: =('Редин'!B61*'Шатков'!B61*'Полищук'!B61)^(1/3) -> 3 | C61: =('Редин'!C61*'Шатков'!C61*'Полищук'!C61)^(1/3) -> 1 | D61: =('Редин'!D61*'Шатков'!D61*'Полищук'!D61)^(1/3) -> 1.5874011 | E61: =('Редин'!E61*'Шатков'!E61*'Полищук'!E61)^(1/3) -> 4.3088694 | I61: =PRODUCT(B61:E61)^(1/4) -> 2.1283488 | J61: =I61/SUM($I$60:$I$63) -> 0.44248956 | K61: =(B61*$J$60+C61*$J$61+D61*$J$62+E61*$J$63)/J61 -> 4.0268964
...

Sheet Итог
A1: Фаза 1 — Итоги чёткого коллективного МАИ
A2: Результаты предварительные: экспертные пары получены из черновых оценок, а не отдельного опроса.
A4: Этап 1. Веса критериев и локальные приоритеты альтернатив
A5: Критерий | B5: Вес критерия | C5: A1 — Pentest | D5: A2 — DevSecOps | E5: A3 — SOC | F5: A4 — Audit | G5: Сумма A1–A4
A6: K1 — Практическая значимость | B6: ='Коллективный'!J9 -> 0.23058414 | C6: ='Коллективный'!J30 -> 0.25827256 | D6: ='Коллективный'!J31 -> 0.26082006 | E6: ='Коллективный'!J32 -> 0.38697161 | F6: ='Коллективный'!J33 -> 0.093935767 | G6: =SUM(C6:F6) -> 1
A7: K2 — Функциональная содержательность | B7: ='Коллективный'!J10 -> 0.13189134 | C7: ='Коллективный'!J45 -> 0.22599311 | D7: ='Коллективный'!J46 -> 0.33860708 | E7: ='Коллективный'!J47 -> 0.33860708 | F7: ='Коллективный'!J48 -> 0.096792722 | G7: =SUM(C7:F7) -> 1
A8: K3 — Потенциал интеграции и развития | B8: ='Коллективный'!J11 -> 0.087059034 | C8: ='Коллективный'!J60 -> 0.15797192 | D8: ='Коллективный'!J61 -> 0.44248956 | E8: ='Коллективный'!J62 -> 0.31457467 | F8: ='Коллективный'!J63 -> 0.084963848 | G8: =SUM(C8:F8) -> 1
A9: K4 — Демонстрационная и исследовательская ценность | B9: ='Коллективный'!J12 -> 0.15948183 | C9: ='Коллективный'!J75 -> 0.40911977 | D9: ='Коллективный'!J76 -> 0.18484072 | E9: ='Коллективный'!J77 -> 0.27967986 | F9: ='Коллективный'!J78 -> 0.12635964 | G9: =SUM(C9:F9) -> 1
A10: K5 — Трудоёмкость реализации MVP | B10: ='Коллективный'!J13 -> 0.22872614 | C10: ='Коллективный'!J90 -> 0.31292253 | D10: ='Коллективный'!J91 -> 0.088193108 | E10: ='Коллективный'!J92 -> 0.12123028 | F10: ='Коллективный'!J93 -> 0.47765409 | G10: =SUM(C10:F10) -> 1
A11: K6 — Внешние зависимости MVP | B11: ='Коллективный'!J14 -> 0.088259875 | C11: ='Коллективный'!J105 -> 0.31219479 | D11: ='Коллективный'!J106 -> 0.07348711 | E11: ='Коллективный'!J107 -> 0.11705103 | F11: ='Коллективный'!J108 -> 0.49726708 | G11: =SUM(C11:F11) -> 1
A12: K7 — Эксплуатация и сопровождение MVP | B12: ='Коллективный'!J15 -> 0.073997633 | C12: ='Коллективный'!J120 -> 0.31657099 | D12: ='Коллективный'!J121 -> 0.077078083 | E12: ='Коллективный'!J122 -> 0.10481801 | F12: ='Коллективный'!J123 -> 0.50153292 | G12: =SUM(C12:F12) -> 1
A13: Контроль суммы весов | B13: =SUM(B6:B12) -> 1
A16: Этап 2. Общий рейтинг
A17: Концепция | B17: Глобальный вес | C17: Место | D17: Проверка | E17: Статус
A18: A1 — Pentest | B18: =$B$6*C6+$B$7*C7+$B$8*C8+$B$9*C9+$B$10*C10+$B$11*C11+$B$12*C12 -> 0.29091349 | C18: =RANK(B18,$B$18:$B$21,0) -> 1 | D18: =IF(B18>=0,"OK","ПРОВЕРИТЬ") -> OK | E18: Черновик
A19: A2 — DevSecOps | B19: =$B$6*D6+$B$7*D7+$B$8*D8+$B$9*D9+$B$10*D10+$B$11*D11+$B$12*D12 -> 0.20516339 | C19: =RANK(B19,$B$18:$B$21,0) -> 4 | D19: =IF(B19>=0,"OK","ПРОВЕРИТЬ") -> OK | E19: Черновик
A20: A3 — SOC | B20: =$B$6*E6+$B$7*E7+$B$8*E8+$B$9*E9+$B$10*E10+$B$11*E11+$B$12*E12 -> 0.25169501 | C20: =RANK(B20,$B$18:$B$21,0) -> 3 | D20: =IF(B20>=0,"OK","ПРОВЕРИТЬ") -> OK | E20: Черновик
A21: A4 — Security Audit | B21: =$B$6*F6+$B$7*F7+$B$8*F8+$B$9*F9+$B$10*F10+$B$11*F11+$B$12*F12 -> 0.25222811 | C21: =RANK(B21,$B$18:$B$21,0) -> 2 | D21: =IF(B21>=0,"OK","ПРОВЕРИТЬ") -> OK | E21: Черновик
A23: Сумма глобальных весов | B23: =SUM(B18:B21) -> 1
A24: Контроль суммы | B24: =IF(ABS(B23-1)<0.000001,"OK","ПРОВЕРИТЬ") -> OK
A27: Этап 3. Проверка согласованности (CR)
A28: Матрица | B28: Редин | C28: Шатков | D28: Полищук | E28: Коллективный
A29: Веса критериев | B29: ='Редин'!I20 -> 0.0059651468 | C29: ='Шатков'!I20 -> 0.0038395343 | D29: ='Полищук'!I20 -> 0.0017085663 | E29: ='Коллективный'!I20 -> 0.00085557124
A30: K1 — альтернативы | B30: ='Редин'!I38 -> 0.0076275135 | C30: ='Шатков'!I38 -> 0.003835658 | D30: ='Полищук'!I38 -> 0.0076275135 | E30: ='Коллективный'!I38 -> 0.0029652623
A31: K2 — альтернативы | B31: ='Редин'!I53 -> 0.003835658 | C31: ='Шатков'!I53 -> 0.0076275135 | D31: ='Полищук'!I53 -> 0 | E31: ='Коллективный'!I53 -> 0.0024731847
A32: K3 — альтернативы | B32: ='Редин'!I68 -> 0.018916771 | C32: ='Шатков'!I68 -> 0.0076275135 | D32: ='Полищук'!I68 -> 0.011473026 | E32: ='Коллективный'!I68 -> 0.010988174
A33: K4 — альтернативы | B33: ='Редин'!I83 -> 0.011473026 | C33: ='Шатков'!I83 -> 0.003835658 | D33: ='Полищук'!I83 -> 0 | E33: ='Коллективный'!I83 -> 0.0028993161
A34: K5 — альтернативы | B34: ='Редин'!I98 -> 0.0076275135 | C34: ='Шатков'!I98 -> 0.029160902 | D34: ='Полищук'!I98 -> 0.0076275135 | E34: ='Коллективный'!I98 -> 0.009513061
A35: K6 — альтернативы | B35: ='Редин'!I113 -> 0.022420083 | C35: ='Шатков'!I113 -> 0.017910309 | D35: ='Полищук'!I113 -> 0.017910309 | E35: ='Коллективный'!I113 -> 0.019352044
A36: K7 — альтернативы | B36: ='Редин'!I128 -> 0.010256472 | C36: ='Шатков'!I128 -> 0.022420083 | D36: ='Полищук'!I128 -> 0.017910309 | E36: ='Коллективный'!I128 -> 0.014565001
A38: Все CR ≤ 0,10? | B38: =IF(MAX(B29:E36)<=0.1,"OK","ПРОВЕРИТЬ") -> OK
A41: Предварительный вывод
A43: Лидер | B43: =IF(C18=1,A18,IF(C19=1,A19,IF(C20=1,A20,A21))) -> A1 — Pentest
A44: Вес лидера | B44: =MAX(B18:B21) -> 0.29091349
A46: Согласованность оценок (CR) не является подтверждением их независимости.
